Workbook
Name \0: #REF!
Name \a: #REF!
Name \b: #REF!
Name \c: #REF!
Name \d: #REF!
Name \f: #REF!
Name \g: #REF!
Name \h: #REF!
Name \i: #REF!
Name \l: #REF!
Name \m: #REF!
Name \o: #REF!
Name \p: '[1]SRC-B3U2'!#REF!
Name \q: #REF!
Name \r: #REF!
Name \s: #REF!
Name \t: #REF!
Name \w: #REF!
Name \x: '[1]SRC-B3U2'!#REF!
Name \y: #REF!
Name \z: #REF!
Name _．共_22頁: #REF!
Name _____________________cpi02: #REF!
Name _____________________cpi59: #REF!
Name _____________________cpi60: #REF!
Name _____________________cpi62: #REF!
Name _____________________cpi63: #REF!
Name _____________________cpi64: #REF!
Name _____________________cpi65: #REF!
Name _____________________cpi66: #REF!
Name _____________________cpi67: #REF!
Name _____________________cpi68: #REF!
Name _____________________cpi69: #REF!
Name _____________________cpi70: #REF!
Name _____________________cpi71: #REF!
Name _____________________cpi72: #REF!
Name _____________________cpi73: #REF!
Name _____________________cpi74: #REF!
Name _____________________cpi75: #REF!
Name _____________________cpi76: #REF!
Name _____________________cpi77: #REF!
Name _____________________cpi78: #REF!
Name _____________________cpi79: #REF!
Name _____________________cpi80: #REF!
Name _____________________cpi81: #REF!
Name _____________________cpi82: #REF!
Name _____________________cpi83: #REF!
Name _____________________cpi84: #REF!
Name _____________________cpi85: #REF!
Name _____________________cpi86: #REF!
Name _____________________cpi87: #REF!
Name _____________________cpi88: #REF!
Name _____________________cpi89: #REF!
Name _____________________cpi90: #REF!
Name _____________________cpi91: #REF!
Name _____________________cpi92: #REF!
Name _____________________cpi93: #REF!
Name _____________________cpi94: #REF!
Name _____________________cpi95: #REF!
Name _____________________cpi96: #REF!

Sheet 可申請獎勵上限
A1: 基地基本資料
A2: 基地面積 | B2: 1029
A3: 建物原容積 | B3: 2000
A4: 使用分區 | B4: 第三種住宅區
A5: 容積率 | B5: 2.25
A6: 法定容積 | B6: =B2*B5 -> 2315.25
A8: 基地資訊與可申請容積獎勵上限設定
A9: 基地 | B9: 法令規定項目 | C9: 原容積 | D9: 法定容積 | E9: 獎勵加成 | F9: 允建上限總容積 | G9: 本案可申請 | H9: 備註
A10: 基地1 | B10: 1.2倍原容積 | C10: =B3 -> 2000 | D10: =B6 -> 2315.25 | E10: 1.2 | F10: =C10*E10 -> 2400 | G10: =F10-C10 -> 400 | H10: 擇優
B11: 原容積+0.3倍法定容積 | C11: =B3 -> 2000 | D11: =B6 -> 2315.25 | E11: 0.3 | F11: =C11+D11*E11 -> 2694.575 | G11: =F11-D11 -> 379.325
B12: 法定容積+0.5倍法定容積 | C12: =B3 -> 2000 | D12: =B6 -> 2315.25 | E12: 0.5 | F12: =D12+D12*E12 -> 3472.875 | G12: =F12-D12 -> 1157.625
A13: 基地2 | B13: 1.2倍原容積 | C13: 0 | D13: 0 | E13: 1.2 | F13: =C13*E13 -> 0 | G13: =F13-C13 -> 0 | H13: 僅適用涉及跨分區之基地
B14: 原容積+0.3倍法定容積 | C14: 0 | D14: 0 | E14: 0.3 | F14: =C14+D14*E14 -> 0 | G14: =F14-D14 -> 0
B15: 法定容積+0.5倍法定容積 | C15: 0 | D15: 0 | E15: 0.5 | F15: =D15+D15*E15 -> 0 | G15: =F15-D15 -> 0
A16: 合計(基地1+基地2) | C16: =MAX(C10:C12)+MAX(C13:C15) -> 2000 | D16: =MAX(D10:D12)+MAX(D13:D15) -> 2315.25 | E16: - | F16: =MAX(F10:F12)+MAX(F13:F15) -> 3472.875 | G16: =MAX(G10:G12)+MAX(G13:G15) -> 1157.625

Sheet 都更獎勵(北市)
E1: 基地面積 | F1: =可申請獎勵上限!B2 -> 1029
E2: 容積率 | F2: =可申請獎勵上限!B5 -> 2.25 | G2: 暫以住三評估
E3: 法定容積樓板 | F3: =可申請獎勵上限!B6 -> 2315.25
A4: 法規 | B4: 獎勵項目 | D4: 獎勵基準 | E4: 擬申請獎勵值 | G4: 核計說明 | H4: 備註 (初擬UI呈現方式)
E5: 獎勵額度(%) | F5: 獎勵面積(㎡)
A6: 都市更新建築容積獎勵辦法 | B6: 第五條 | D6: 實施容積管制前已興建完成之合法建築物，其原建築容積高於基準容積者，得依原建築容積建築，或依原建築基地基準容積之10%給予獎勵容積。 | E6: 0 | F6: =$F$3*E6 -> 0 | G6: 視個案狀況，應以使照存根面積打折估算；原容積應請建築師依據使照竣工圖核算並簽證後函請建管單位確認是否高於基準容積 | H6: 獎勵值填空
B7: 第六條 | D7: 都市更新事業計畫範圍內之建築物符合下列情形之一者，依原建築基地基準容積一定比率給予獎勵容積： 1.經建築主管機關依建築法規、災害防救法規通知限期拆除、逕予強制拆除或評估有危險之虞應限期補強或拆除：10% 2.經結構安全性能評估結果未達最低等級：8% | E7: 0.08 | F7: =$F$3*E7 -> 185.22 | G7: 視個案狀況，以有謄本或使用執照之建築物經結構初評未達最低等級計算；有建物謄本無使用執照之建物，應請建築師檢討是否可以申請認定為合法建築且需取得該棟建築物100%地主同意；另需請結構技師或相關專業技師針對合法建築物鑑定及評估 | H7: 獎勵值下拉表單 (10%、8%)
B8: 第七條 | D8: 依主管機關公告提供指定之社會福利設施或其他公益設施，建築物及其土地產權無償登記為公有者，除不計入容積外，其獎勵額度以基準容積之30%為上限 | E8: 0 | F8: =$F$3*E8 -> 0 | G8: 視個案狀況，並應以主管機關公告指定社會福利設施或其他公益設施為主 | H8: 獎勵值填空
B9: 第八條 | D9: 協助取得及開闢都市更新事業計畫範圍內或其周邊公共設施用地，產權登記為公有者，其獎勵額度以基準容積之15%為上限 | E9: 0 | F9: =$F$3*E9 -> 0 | G9: 視個案狀況，協助取得及開闢道路用地應取得土地捐贈同意書 | H9: 獎勵值填空
B10: 第九條 | D10: 都市更新事業計畫範圍內之古蹟、歷史建築、紀念建築及聚落建築群，辦理整體性保存、修復、再利用及管理維護者，除不計入容積外，並得依該建築物實際面積之1.5倍，給予獎勵容積；而依本條例第36條第11款規定保存或維護計畫辦理之都市計畫表明應予保存或有保存價值建築物，除不計入容積外，並得依該建築物之實際面積，給予獎勵容積 | E10: 0 | F10: =$F$3*E10 -> 0 | G10: 視個案區位是否涉及古蹟、歷史建築等 | H10: 獎勵值填空
B11: 第十條 | D11: 取得候選綠建築證書，依下列等級給予獎勵容積： 鑽石級：10%；黃金級：8%；銀級：6%；銅級：4%；合格級：2% (銅級及合格級，僅限面積未達五百平方公尺者適用) | E11: 0.06 | F11: =$F$3*E11 -> 138.915 | G11: 視個案狀況與建築師討論結果而定，暫以取得綠建築銀級候選證書估計。 | H11: 獎勵值下拉表單 (10%、8%、6%、4%、2%)
B12: 第十一條 | D12: 取得候選智慧建築證書，依下列等級給予獎勵容積： 鑽石級：10%；黃金級：8%；銀級：6%；銅級：4%；合格級：2% (銅級及合格級，僅限面積未達五百平方公尺者適用) | E12: 0.06 | F12: =$F$3*E12 -> 138.915 | G12: 視個案狀況與建築師討論結果而定，暫以取得智慧建築銀級候選證書估計 | H12: 獎勵值下拉表單 (10%、8%、6%、4%、2%)
B13: 第十二條 | D13: 採無障礙環境設計者，依下列規定給予獎勵容積(住宅適用)： 1.取得無障礙住宅建築標章：5% 2.依住宅性能評估實施辦法辦理新建住宅性能評估之無障礙環境： 第一級：4%；第二級：3% | E13: 0.03 | F13: =$F$3*E13 -> 69.4575 | G13: 視個案狀況與建築師討論結果而定 暫以依住宅性能評估實施辦法辦理新建住宅性能評估之無障礙環境第二級估計 | H13: 獎勵值下拉表單(5%、4%、3%)
B14: 第十三條 | D14: 採建築物耐震設計者，依下列規定給予獎勵容積： 1.取得耐震設計標章：10% 2.依住宅性能評估實施辦法辦理新建住宅性能評估之結構安全性能： 第一級：6%；第二級：4%；第三級：2% (住宅適用) | E14: 0.02 | F14: =$F$3*E14 -> 46.305 | G14: 視個案狀況與建築師討論結果而定 暫以依住宅性能評估實施辦法辦理新建住宅性能評估之結構安全性能第三級估計 | H14: 獎勵值下拉表單 (10%、6%、4%、2%)
B15: 第十四條 | D15: 本辦法108.5.15修正之條文施行日起一定期間內，擬訂都市更新事業計畫報核者，依下列規定給予獎勵容積： 1.劃定應實施更新地區：修正施行日起五年內：10%；前述期間屆滿之次日起五年內：5% 2.未經劃定應實施更新地區：修正施行日起五年內：7%；前述期間屆滿之次日起五年內：3.5% | E15: 0.05 | F15: =$F$3*E15 -> 115.7625 | G15: 視個案基地區位是否位於更新地區而定 暫以劃定應實施更新地區，於113.5.16至118.5.16之期間內擬定都更事業計畫報核估計 | H15: 獎勵值下拉表單 (5%、3.5%)
B16: 第十五條 | D16: 都市更新事業計畫範圍重建區段含一個以上完整計畫街廓或土地面積達一定規模以上者，依下列規定給予獎勵容積： 1.一個以上完整計畫街廓：5% 2.面積達3,000㎡以上未滿10,000㎡：5%，每增加100㎡，另給予基準容積0.3% 3.面積達10,000㎡以上：30% | E16: 0 | F16: =$F$3*E16 -> 0 | G16: 視個案基地區位是否位於更新地區而定 暫以劃定應實施更新地區，於113.5.16至118.5.16之期間內擬定都更事業計畫報核估計 | H16: 獎勵值填空
B17: 第十六條 | D17: 更新前門牌戶達二十戶以上，依本條例第43條第1項但書後段規定，於都市更新事業計畫報核時經全體土地及合法建築物所有權人同意以協議合建方式實施之都市更新事業，給予基準容積之5%獎勵容積 | E17: 0 | F17: =$F$3*E17 -> 0 | G17: 視個案狀況而定 | H17: 獎勵值下拉表單 (5%)
B18: 第十七條 | D18: 處理占有他人土地之舊違章建築戶，依都市更新事業計畫報核前之實測面積給予獎勵容積，且每戶不得超過最近一次行政院主計總處人口及住宅普查報告各該直轄市、縣（市）平均每戶住宅樓地板面積，其獎勵額度以基準容積之20%為上限 | E18: 0 | F18: =$F$3*E18 -> 0 | G18: 視個案狀況而定，舊違章戶之認定以民國77年8月1日以前興建完成者為限，並以實測面積為準 | H18: 獎勵值填空
B19: 小計 | E19: =SUM(E6:E18) -> 0.3 | F19: =SUM(F6:F18) -> 694.575
A20: 臺北市都市更新建築容積獎勵辦法 | B20: 一、都市環境之貢獻 | C20: 建築規劃設計(一) | D20: 符合下列3項者，給予1%；符合4項者，給予2%；符合5項以上者，給予3%。 1.建築物鄰8公尺以下道路境界線之退縮，自人行道及建築物高度比檢討範圍外起算，一側建築物退縮距離達2公尺以上。 2.建築物與鄰地境界線距離平均寬度達3公尺，最小淨寬達2公尺以上。 3.基地內留設寬度4公尺以上供公眾通行之通道，最小淨寬達2.5公尺以上，且通道兩端均銜接公共設施用地或道路。 4.建築基地集中設置開放空間廣場達200平方公尺以上，其任一邊最小淨寬達8公尺以上，且長寬比不得超過三。 5.建築物地面層鄰接公共空間側留設供公眾使用之挑高半戶外空間，其樑下淨高達6公尺以上，留設面積達36平方公尺以上，任一邊最小淨寬達6公尺以上，且長寬比不得超過3。 6.建築物斜對角距離平均未超過45公尺；倘超過45公尺，以設計手法規劃建物立面，避免形成連續性牆面。 | E20: 0 | F20: =$F$3*E20 -> 0 | G20: 視個案狀況與建築師檢討結果而定 | H20: 獎勵值下拉表單 (2%、3%)
C21: 建築規劃設計(二) | D21: 基地設置雨水流出抑制設施，達法定雨水貯留量二倍以上，給予1%獎勵。 1.法定雨水貯留量依「臺北市基地開發排入雨水下水道逕流量標準」規定，視基地規模檢討之 2.應檢附相關設施及排水系統分析資料、圖說 | E21: 0.01 | F21: =$F$3*E21 -> 23.1525 | G21: 視個案狀況與建築師設計內容而定 暫以基地設置雨水流出抑制設施，達法定雨水貯留量二倍以上，申請1%獎勵估算 | H21: 獎勵值下拉表單 (1%)
C22: 建築規劃設計(三) | D22: 基地面臨都市計畫道路、公共設施或指定建築線之既成巷道沿街面，留設供人行走之地面道路或騎樓且具延續性，並配合基地周遭相鄰街廓整體考量設置，無遮簷部分須以滲透設計，其設計經由建築師簽證。 1.留設供人行走之地面道路或騎樓，各部分淨寬均達2公尺以上至6公尺以下，依實際留設面積給予獎勵。 2.依都市計畫、臺北市土地使用分區管制自治條例及其他法令規定留設供人行走之地面道路或騎樓，須留設法定規定以上之供人行走地面道路或騎樓，始得申請本項獎勵。 | E22: 0 | F22: =$F$3*E22 -> 0 | G22: 視個案狀況與建築師設計內容而定 | H22: 獎勵值填空
C23: 建築規劃設計(四) | D23: 符合臺北市都市更新及爭議處理審議會歷次會議通案重要審議原則之建築設計類別全部審議原則者，給予3%。 | E23: 0.03 | F23: =$F$3*E23 -> 69.4575 | G23: 視個案狀況與建築師設計內容而定 暫以3%估算 | H23: 獎勵值下拉表單 (3%)
C24: 建築規劃設計(五) | D24: 建築物採屋頂平臺綠化及立面方式垂直綠化，綠覆率達「臺北市新建建築物綠化實施規則」以下簡稱本規則第五條所定各類建築基地綠覆率一點六倍以上，且屋頂平臺及立面方式垂直綠覆面積占總綠覆面積二分之一以上者。下列三項計算方式擇一適用： 1.依本規則計算達各類建築基地綠覆率1.6倍以上，未滿1.8倍者，給予基準容積2%。 2.依本規則計算達各類建築基地綠覆率1.8倍以上，未滿2倍者，給予基準容積3%。 3.依本規則計算達各類建築基地綠覆率2倍以上者，給予基準容積4%。 | E24: 0 | F24: =$F$3*E24 -> 0 | G24: 視個案狀況與建築師設計內容而定 | H24: 獎勵值下拉表單 (2%、3%、4%)
C25: 改善都市環境 | D25: 協助建築基地所坐落同一街廓或毗鄰街廓整修順平騎樓或無遮簷人行道，並取得其土地及建物全體所有權人同意自行維護管理文件者。整修一棟建築物之騎樓、無遮簷人行道，給予0.25%獎勵。 | E25: 0 | F25: =$F$3*E25 -> 0 | G25: 視個案狀況與建築師設計內容而定 | H25: 獎勵值下拉表單 (0.25%)
B26: 二、新技術之應用 | C26: 新技術應用 | D26: 建築基地之法定停車位總數量以外，所提供之充電汽車及機車停車位，其數量達法定停車位總數量3%以上，給予1%獎勵。 1.充電汽車及機車停車位為社區共用車位，其管理規範應納入住戶管理規約。 2.充電柱之設備規格，得比照臺北市停車管理工程處接受民間充電柱捐贈注意事項之規定辦理。 | E26: 0.01 | F26: =$F$3*E26 -> 23.1525 | G26: 視個案狀況與建築師設計內容而定 暫以提供足量充電車位，獎勵1%估算 | H26: 獎勵值下拉表單 (1%)
B27: 三、有助於都市更新事業之實施 | C27: 促進都市更新(一) | D27: 提供經費予本市都市更新基金，有助於推動都市更新事業之實施 獎勵容積＝(提供經費予本市都市更新基金金額)/(都市更新事業計畫報核日當期之建築基地平均公告現值×0.7) 申請本項獎勵於事業計畫核定時應與本府簽訂契約書，並應於領得使用執照前完成提供經費作業。 | E27: 0 | F27: =$F$3*E27 -> 0 | G27: 視個案狀況 | H27: 獎勵值填空
C28: 促進都市更新(二) | D28: 更新單元內現有合法建築物之屋齡達30年以上，且樓層數達四、五層樓無設置電梯設備或法定停車位數低於戶數7/10以下者 1.合法建築物為四層樓者，給予該棟合法建築物坐落之建築基地基準容積之2% 2.合法建築物為五層樓者，給予該棟合法建築物坐落之建築基地基準容積之4% | E28: 0.02 | F28: =$F$3*E28 -> 46.305 | G28: 視個案狀況 暫以四層樓且無設置電梯、法停低於戶數7/10以下計算 | H28: 獎勵值下拉表單 (2%、4%)
B29: 小計 | E29: =SUM(E20:E28) -> 0.07 | F29: =$F$3*E29 -> 162.0675
A30: 都更容獎總計 | E30: =E29+E19 -> 0.37 | F30: =$F$3*E30 -> 856.6425 | G30: 上限為法定容積50%或原建築容積+法定容積30%
A31: 臺北市防災型都市更新細部計畫 | D31: 民國63年以前之建物，或依「都市更新耐震能力不足建築物而有明顯危害公共安全認定辦法」規定，經結構安全性能評估初評或詳評結果認定，評估結果ID值小於0.35之建築物，依各建築物原建築基地面積計算獎勵值 | E31: 0.3 | F31: =$F$3*E31 -> 694.575 | G31: 視個案狀況，由結構技師評估 | H31: 獎勵值填空
A32: 臺北市大眾運輸導向(TOD)開發許可獎勵 | C32: △D1 | D32: 移設捷運設施或增設捷運出入口 容積獎勵按設施所占樓地板面積依地面層1倍、地下層及地上二層以上各0.5倍總和計算之 | E32: 0 | F32: =$F$3*E32 -> 0 | G32: 視個案狀況及基地區位 | H32: 獎勵值填空
C33: △D2 | D33: 設置自行車轉乘停放空間 依實際留設面積給予容積獎勵 | E33: 0 | F33: =$F$3*E33 -> 0 | G33: 基地提供設置公共自行車停車空間或提供公眾使用之一般自行車停車空間者，該自行車空間應留設於地面層且臨道路側。 | H33: 獎勵值填空
C34: △D3 | D34: 留設友善人行空間：標準級、進階級擇一 標準級： 1.基地退縮：臨8公尺以下道路退縮達2公尺以上 2.基地退縮：與鄰地境界線距離平均寬度達3公尺、最小淨寬達2公尺 3.人行通道：基地內留設寬4公尺以上之通道，最小淨寬達2.5公尺以上，且兩端均銜接公設用地或道路 4.開放空間：集中設置開放空間廣場達200平方公尺以上，最小淨寬達8公尺 5.附頂蓋開放空間：地面層鄰接開放空間側留設挑高半戶外空間，樑下淨高達6公尺以上，面積達36平方公尺以上，最小淨寬達6公尺以上 6.環境設計：建物斜對角距離平均未超過45公尺 前述符合3項以上：1%；4項以上：2%；5項以上：3% 7.人行通道騎樓設置：淨寬均達2公尺至6公尺，依實際留設面積給予容積獎勵 8.友善人行：協助基地同一街廓或毗鄰街廓整修騎樓或人行道，1棟給予基準容積0.25% 進階級： 1.基地退縮：臨8公尺以下道路退縮達4公尺以上 2.基地退縮：與鄰地境界線距離平均寬度達6公尺、最小淨寬達4公尺 3.人行通道：基地內留設寬8公尺以上之通道，最小淨寬達4公尺以上，且兩端均銜接公設用地或道路 4.開放空間：集中設置開放空間廣場達300平方公尺以上，最小淨寬達10公尺 5.附頂蓋開放空間：地面層鄰接開放空間側留設挑高半戶外空間，樑下淨高達6公尺以上，面積達72平方公尺以上，最小淨寬達8公尺以上 6.環境設計：建物斜對角距離平均未超過45公尺 前述符合3項以上：2%；4項以上：4%；5項以上：6% 7.人行通道騎樓設置：淨寬均達2公尺至6公尺，依實際留設面積給予容積獎勵 8.友善人行：協助基地同一街廓或毗鄰街廓整修騎樓或人行道，1棟給予基準容積0.25% | E34: 0 | F34: =$F$3*E34 -> 0 | G34: 視個案狀況與建築師設計內容而定 | H34: 獎勵值填空
C35: △D4 | D35: 回饋公益設施空間 | E35: 0 | F35: =$F$3*E35 -> 0 | H35: 獎勵值填空
C36: △D5 | D36: 繳納代金(應繳納本容積獎勵值50%之回饋代金) | E36: 0 | F36: =$F$3*E36 -> 0 | H36: 獎勵值填空
C37: 小計 | E37: =SUM(E32:E36) -> 0 | F37: =SUM(F32:F36) -> 0 | G37: 上限為第一級場站核心區(30%)、一般區(15%)；第二級場站核心區(20%)、一般區(10%)
A38: 容積移轉 | D38: 上限為基準容積30% (實施都市更新地區、整體開發地區或面臨永久性空地可酌增至40%) | E38: 0 | F38: =$F$3*E38 -> 0 | G38: 視個案狀況與設計內容而定
A39: 增額容積 | D39: 一般區上限為基準容積40%、核心區上限為基準容積50%) | E39: 0 | F39: =$F$3*E39 -> 0 | G39: 視個案狀況與設計內容而定
A40: 合計 | E40: =E30+E37+E38+E39 -> 0.37 | F40: =F30+F37+F38+F39 -> 856.6425

Sheet 北市建築量體
A1: 建築量體分析表
E2: 地主比例 | F2: 公司比例
B3: 台北市 | E3: =1-F3 -> 0.6 | F3: 0.4 | G3: 案件編號： | I3: 數值需手動輸入
A4: 個案基本資料 | B4: 基地位置
B5: 基地地段
B6: 基地面積 | C6: ='都更獎勵(北市)'!F1 -> 1029 | E6: =C6*0.3025 -> 311.2725
B7: 法定建蔽率/容積率 | C7: =(C8*D8+C9*D9)/C6 -> 0.45 | E7: =(C8*E8+C9*E9)/C6 -> 2.25
B8: 分區-第3種住宅區 | C8: =C6 -> 1029 | D8: 0.45 | E8: 2.25 | F8: 0.8
B9: 分區-道路 | C9: =C6-C8 -> 0 | D9: 0 | E9: 0
B10: 面前道路寬度 | C10: 11 | E10: ○○街(11M)
B11: 建築量體 | C11: =C49&"F/B"&E35 -> 12F/B4 | E11: 建築型態 | F11: 住宅 | G11: 依實際設計計算
A12: 量 體 分 析 項 目 | C12: 平方公尺 | D12: 坪 | E12: 其他/合計 | G12: 計算式說明
A13: 建築基地 | B13: 可用基地面積 | C13: =C8 -> 1029 | D13: =C13*0.3025 -> 311.2725
B14: 法定騎樓面積 | C14: 0 | D14: =C14*0.3025 -> 0
B15: 法定建築面積 | C15: =MIN((C6*C7),C13*E15) -> 463.05 | D15: =C15*0.3025 -> 140.07262 | E15: =D8 -> 0.45
B16: 實設建築面積 | C16: =(C14+C23+C24+C25+C26)/C49 -> 397.04507 | D16: =C16*0.3025 -> 120.10613 | E16: =C16/C13 -> 0.38585526 | G16: (地上樓板面積－屋突面積)/設計樓層
A17: 允建總容積 | B17: 基準容積 | C17: =C6*E7 -> 2315.25 | D17: =C17*0.3025 -> 700.36312 | E17: =E7 -> 2.25
B18: 容積移轉(需費用) | C18: =$C$17*E18 -> 0 | D18: =C18*0.3025 -> 0 | E18: 0
B19: 防災/危老獎勵值 | C19: =$C$17*E19 -> 0 | D19: =C19*0.3025 -> 0 | E19: 0
B20: 都市更新獎勵容積 | C20: =$C$17*E20 -> 1620.675 | D20: =C20*0.3025 -> 490.25419 | E20: 0.7 | G20: 都更獎勵50%+道路容移0%+防災20%
B21: 其他土管獎勵容積 | C21: =$C$17*E21 -> 0 | D21: =C21*0.3025 -> 0 | E21: 0
B22: 獎勵容積總合 | C22: =$C$17*E22 -> 1620.675 | D22: =C22*0.3025 -> 490.25419 | E22: =E19+E20+E21 -> 0.7
B23: 允建總容積 | C23: =C17+C18+C22 -> 3935.925 | D23: =C23*0.3025 -> 1190.6173 | E23: =E17*(1+E18+E22) -> 3.825 | G23: 獎勵上限50%， 基準容積+容移增加容積+土管獎勵容積
A24: 地上層建築面積 | B24: 機房免計容積 | C24: =(C23)*E24 -> 590.38875 | D24: =C24*0.3025 -> 178.5926 | E24: 0.15 | G24: (可建總容積－停獎增加容積－海砂屋獎勵容積)×15%
B25: 梯廳免計容積面積 | C25: =(C23+C24)/0.95*E25 -> 238.22704 | D25: =C25*0.3025 -> 72.063679 | E25: 0.05 | G25: (可建總容積+機房免計容積)/0.95×5%
B26: 1F車道 + 人行步道面積 | C26: 0 | D26: =C26*0.3025 -> 0
B27: 屋突總面積 | C27: =C13*E16*1/8*E27 -> 148.8919 | D27: =C27*0.3025 -> 45.0398 | E27: 3 | G27: (可用基地面積×規劃建蔽率)/8×屋突樓層數
B28: 陽台面積 | C28: =(C23+C24)/0.95*E28 -> 476.45408 | D28: =C28*0.3025 -> 144.12736 | E28: 0.1 | G28: (可建總容積+機房免計容積)/0.95×10%
B29: 不計入容積雨遮 | C29: =C23*E29 -> 0 | D29: =C29*0.3025 -> 0 | E29: 0 | G29: 可建總容積×雨遮所佔總容積比例
A30: 地下層建築面積 | B30: 汽車停車位 | C30: =ROUNDUP((C23+C24+C25)/120,0) -> 40 | D30: 16 | E30: =C30+D30 -> 56 | G30: =ROUNDUP((C23+C24+C25)/120,0)
B31: 機車位 / 腳踏車位 | C31: =ROUNDUP((C23+C24+C25)/100,0) -> 48 | D31: 20 | E31: =SUM(C31:D31) -> 68 | G31: =ROUNDUP((C23+C24+C25)/100,0)
B32: 汽車位面積 | C32: =E30*E32 -> 2240 | D32: =C32*0.3025 -> 677.6 | E32: 40 | G32: 停車位數量×停車位面積 ※假設機械車位面積為25m2
B33: 機車位面積 | C33: =C31*E33 -> 192 | D33: =C33*0.3025 -> 58.08 | E33: 4 | G33: 機車位數量×機車位面積
B34: 腳踏車位面積 | C34: =D31*E34 -> 29.6 | D34: =C34*0.3025 -> 8.954 | E34: 1.48 | G34: 腳踏車位數量*腳踏車位面積(0.8m*1.85m=1.48) ※腳踏車位假設在一樓
B35: 地下層單層面積 | C35: =C13*F8 -> 823.2 | D35: =C35*0.3025 -> 249.018 | E35: =D40 -> 4 | G35: 可用基地面積×規劃開挖率
B36: 地下層樓梯間面積 | C36: =C13*C7/8*E35 -> 231.525 | D36: =C36*0.3025 -> 70.036312
B37: 地下層機房 | C37: =C23*E37 -> 196.79625 | D37: =C37*0.3025 -> 59.530866 | E37: 0.05 | G37: 可建總容積×地下層機房所佔總容積比例
B38: 地下室可增設公設面積 | C38: =(1-COUNTA(E40))*(D40*C35-C39) -> 664.00375 | D38: =C38*0.3025 -> 200.86113 | E38: =IF(ROUNDUP((C38+C39)/C35,0)-D40=0,"OK","公設比有誤") -> OK | F38: =C38/(C35*D40) -> 0.20165323 | G38: 地下室開挖層數×地下層單層面積－地下室開挖面積概估
B39: 地下室開挖面積概估 | C39: =C37+C32+C33+C34-C34 -> 2628.7962 | D39: =C39*0.3025 -> 795.21087 | G39: 機車位面積+汽車位面積+地下層機房
B40: 地下室開挖層數 | C40: =C39/C35 -> 3.1933871 | D40: =ROUNDUP(C40,0) -> 4 | G40: 地下室開挖面積概估/地下層單層面積
...

Sheet 新北建築量體
A1: 建築量體分析表
E2: 地主比例 | F2: 公司比例
B3: 新北市 | E3: =1-F3 -> 0 | F3: 1 | G3: 案件編號： | J3: 數值需手動輸入
A4: 個案基本資料 | B4: 基地位置
B5: 基地地段
B6: 基地面積 | C6: 643.55 | E6: =C6*0.3025 -> 194.67387
B7: 法定建蔽率/容積率 | C7: =(C8*D8+C9*D9)/C6 -> 0.5 | E7: =(C8*E8+C9*E9)/C6 -> 2
B8: 分區-商3 | C8: =C6-C9 -> 0 | D8: 0 | E8: 0 | F8: 0.6777
B9: 分區-住宅區 | C9: 643.55 | D9: 0.5 | E9: 2 | G9: 法定開挖率上限:((643.55-500)x60%+(500x70%))/643.55=67.77%
B10: 面前道路寬度 | C10: 6 | E10: 計畫道路
B11: 建築量體 | C11: =C49&"F/B"&E35 -> 11F/B2 | E11: 建築型態 | F11: 住宅 | G11: 依實際設計計算
A12: 量 體 分 析 項 目 | C12: 平方公尺 | D12: 坪 | E12: 其他/合計 | G12: 計算式說明
A13: 建築基地 | B13: 可用基地面積 | C13: =C6 -> 643.55 | D13: =C13*0.3025 -> 194.67387
B14: 法定騎樓面積 | C14: 0 | D14: =C14*0.3025 -> 0
B15: 法定建築面積 | C15: =MIN((C6*C7),C13*E15) -> 321.775 | D15: =C15*0.3025 -> 97.336937 | E15: =C7 -> 0.5
B16: 實設建築面積 | C16: =(C14+C23+C24+25+C26)/C49 -> 224.29748 | D16: =C16*0.3025 -> 67.849987 | E16: =C16/C13 -> 0.34853155 | G16: (地上樓板面積－屋突面積)/設計樓層 或=(C14+C23+C24+25+C26)/C49
A17: 允建總容積 | B17: 基準容積 | C17: =C6*E7 -> 1287.1 | D17: =C17*0.3025 -> 389.34775
B18: 容積移轉(需費用) | C18: =$C$17*E18 -> 193.065 | D18: =C18*0.3025 -> 58.402162 | E18: 0.15 | G18: 本案僅能繳納容移代金
B19: 防災/危老獎勵值 | C19: =$C$17*E19 -> 643.55 | D19: =C19*0.3025 -> 194.67387 | E19: 0.5 | G19: 走防災都更2.0 都計變更程序
B20: 都市更新獎勵容積 | C20: =$C$17*E20 -> 0 | D20: =C20*0.3025 -> 0 | E20: 0 | G20: 原容積推算
B21: 其他土管獎勵容積 | C21: =$C$17*E21 -> 0 | D21: =C21*0.3025 -> 0 | E21: 0
B22: 獎勵容積總合 | C22: =$C$17*E22 -> 643.55 | D22: =C22*0.3025 -> 194.67387 | E22: =E19+E20+E21 -> 0.5 | G22: 新北市獎勵上限20%
B23: 允建總容積 | C23: =C17+C18+C22 -> 2123.715 | D23: =C23*0.3025 -> 642.42379 | E23: =E18+E22 -> 0.65 | G23: 基準容積+容移增加容積+開放空間獎勵容積+都更獎勵容積+海砂屋獎勵容積+土管獎勵容積
A24: 地上層建築面積 | B24: 機房免計容積 | C24: =(C23)*E24 -> 318.55725 | D24: =C24*0.3025 -> 96.363568 | E24: 0.15 | G24: (可建總容積－停獎增加容積－海砂屋獎勵容積)×15%
B25: 梯廳免計容積面積 | C25: =(C23+C24)/0.95*E25 -> 128.54064 | D25: =C25*0.3025 -> 38.883545 | E25: 0.05 | G25: (可建總容積+機房免計容積)/0.95×5%
B26: 1F車道 + 人行步道面積 | C26: 0 | D26: =C26*0.3025 -> 0
B27: 屋突總面積 | C27: =C13*E16*1/8*E27 -> 84.111554 | D27: =C27*0.3025 -> 25.443745 | E27: 3 | G27: (可用基地面積×規劃建蔽率)/8×屋突樓層數
B28: 陽台面積 | C28: =(C23+C24)/0.95*E28 -> 257.08129 | D28: =C28*0.3025 -> 77.76709 | E28: 0.1 | G28: (可建總容積+機房免計容積)/0.95×10%
B29: 不計入容積雨遮 | C29: =C23*E29 -> 0 | D29: =C29*0.3025 -> 0 | E29: 0 | G29: 可建總容積×雨遮所佔總容積比例
A30: 地下層建築面積 | B30: 汽車停車位 | C30: =ROUNDUP((C23+C24+C25)/150,0) -> 18 | D30: 4 | E30: =C30+D30 -> 22 | G30: =ROUNDUP((C23+C24+C25)/150,0)
B31: 機車位 / 腳踏車位 | C31: =E30+7 -> 29 | D31: =C31*0.25-2 -> 5.25 | E31: =SUM(C31:D31) -> 34.25 | G31: 新北市一戶一機車+腳踏車位數量(機車位*0.25)
B32: 汽車位面積 | C32: =E30*E32 -> 550 | D32: =C32*0.3025 -> 166.375 | E32: 25 | G32: 停車位數量×停車位面積 ※假設機械車位面積為25m2
B33: 機車位面積 | C33: =C31*E33 -> 116 | D33: =C33*0.3025 -> 35.09 | E33: 4 | G33: 機車位數量×機車位面積
B34: 腳踏車位面積 | C34: =D31*E34 -> 7.77 | D34: =C34*0.3025 -> 2.350425 | E34: 1.48 | G34: 腳踏車位數量*腳踏車位面積(0.8m*1.85m=1.48) ※腳踏車位假設在一樓
B35: 地下層單層面積 | C35: =C13*F8 -> 436.13383 | D35: =C35*0.3025 -> 131.93049 | E35: =D40 -> 2 | G35: 可用基地面積×規劃開挖率
B36: 地下層樓梯間面積 | C36: =C13*C7/8*E35 -> 80.44375 | D36: =C36*0.3025 -> 24.334234
B37: 地下層機房 | C37: =C23*E37 -> 106.18575 | D37: =C37*0.3025 -> 32.121189 | E37: 0.05 | G37: 可建總容積×地下層機房所佔總容積比例
B38: 地下室可增設公設面積 | C38: =(1-COUNTA(E40))*(D40*C35-C39) -> 100.08192 | D38: =C38*0.3025 -> 30.274781 | E38: =IF(ROUNDUP((C38+C39)/C35,0)-D40=0,"OK","公設比有誤") -> OK | F38: =C38/(C35*D40) -> 0.11473762 | G38: 地下室開挖層數×地下層單層面積－地下室開挖面積概估
B39: 地下室開挖面積概估 | C39: =C37+C32+C33+C34-C34 -> 772.18575 | D39: =C39*0.3025 -> 233.58619 | G39: 機車位面積+汽車位面積+地下層機房
B40: 地下室開挖層數 | C40: =C39/C35 -> 1.7705248 | D40: =ROUNDUP(C40,0) -> 2 | G40: 地下室開挖面積概估/地下層單層面積
...
